<mujoco model="panda_urdf_aligned">
  <compiler angle="radian" meshdir="./mesh" texturedir="./texture"/>

  <default>
    <geom contype="1" conaffinity="1" condim="3" friction="0.85 0.85 0.001"/>
    <site rgba="0.5 0.5 0.5 0.3"/>
  </default>

  <asset>
    <mesh name="link0" file="link0.obj"/>
    <mesh name="link1" file="link1.obj"/>
    <mesh name="link2" file="link2.obj"/>
    <mesh name="link3" file="link3.obj"/>
    <mesh name="link4" file="link4.obj"/>
    <mesh name="link5" file="link5.obj"/>
    <mesh name="link6" file="link6.obj"/>
    <mesh name="link7" file="link7.obj"/>
    <mesh name="hand" file="hand.obj"/>
    <mesh name="finger" file="finger.obj"/>

    <texture name="panda" file="panda.png" type="2d"/>
    <material name="panda" texture="panda" shininess=".4" specular=".4"/>
    <material name="panda_white" rgba="1 1 1 1" shininess="0.4" specular="0.4"/>
  </asset>

  <actuator>
    <motor name="panda_joint1" joint="panda_joint1" ctrllimited="true" ctrlrange="-87 87" forcelimited="true" forcerange="-87 87"/>
    <motor name="panda_joint2" joint="panda_joint2" ctrllimited="true" ctrlrange="-87 87" forcelimited="true" forcerange="-87 87"/>
    <motor name="panda_joint3" joint="panda_joint3" ctrllimited="true" ctrlrange="-87 87" forcelimited="true" forcerange="-87 87"/>
    <motor name="panda_joint4" joint="panda_joint4" ctrllimited="true" ctrlrange="-87 87" forcelimited="true" forcerange="-87 87"/>
    <motor name="panda_joint5" joint="panda_joint5" ctrllimited="true" ctrlrange="-12 12" forcelimited="true" forcerange="-12 12"/>
    <motor name="panda_joint6" joint="panda_joint6" ctrllimited="true" ctrlrange="-12 12" forcelimited="true" forcerange="-12 12"/>
    <motor name="panda_joint7" joint="panda_joint7" ctrllimited="true" ctrlrange="-12 12" forcelimited="true" forcerange="-12 12"/>
    <general name="panda_actuator_finger" tendon="panda_split"
             forcelimited="true" forcerange="-35 35"
             ctrllimited="true" ctrlrange="-30 30"
             gainprm="0.3568627451 0 0"
             biasprm="0 -100 -10"/>
  </actuator>

  <worldbody>
    <body name="panda_link0">
      <geom type="mesh" material="panda" mesh="link0"/>
      <inertial pos="-0.025566 -2.87883e-05 0.057332" mass="2.814271300104062"
                fullinertia="0.0075390636364814695 0.010508017427382959 0.009864933638708275 -1.5053124574783335e-05 -0.0012144328835738973 1.0434803501032979e-05"/>

      <body name="panda_link1" pos="0 0 0.333">
        <joint name="panda_joint1" pos="0 0 0" axis="0 0 1" limited="true" range="-2.897246558310587 2.897246558310587" damping="21.75" frictionloss="3.48"/>
        <geom type="mesh" material="panda_white" mesh="link1"/>
        <inertial pos="-3.72212e-09 -0.0324958 -0.0675818" mass="2.6433170427227215"
                  fullinertia="0.017405076982879724 0.015352077935781732 0.005987891663073857 -8.687986369621078e-09 -1.6277819062920423e-08 0.004510855959102245"/>

        <body name="panda_link2" pos="0 0 0" quat="0.7071067811865476 -0.7071067811865475 0 0">
          <joint name="panda_joint2" pos="0 0 0" axis="0 0 1" limited="true" range="-1.7627825445142729 1.7627825445142729" damping="21.75" frictionloss="3.48"/>
          <geom type="mesh" material="panda_white" mesh="link2"/>
          <inertial pos="3.17833e-07 -0.06861 0.0322285" mass="2.6652755331661186"
                    fullinertia="0.01778694005635383 0.006044133867952844 0.01571095500455695 8.70635625879119e-08 3.752072058394008e-08 -0.004599490295490376"/>

          <body name="panda_link3" pos="0 -0.316 0" quat="0.7071067811865476 0.7071067811865475 0 0">
            <joint name="panda_joint3" pos="0 0 0" axis="0 0 1" limited="true" range="-2.897246558310587 2.897246558310587" damping="21.75" frictionloss="3.48"/>
            <geom type="mesh" material="panda" mesh="link3"/>
            <inertial pos="0.0469893 0.0316374 -0.031704" mass="2.3293714829045733"
                      fullinertia="0.0075496764161139766 0.009680676080191398 0.007944557422008086 -0.0024320464513492225 -0.003250815048103007 -0.0021316282421730694"/>

            <body name="panda_link4" pos="0.0825 0 0" quat="0.7071067811865476 0.7071067811865475 0 0">
              <joint name="panda_joint4" pos="0 0 0" axis="0 0 1" limited="true" range="-3.07177948351002 -0.06981317007977318" damping="21.75" frictionloss="3.48"/>
              <geom type="mesh" material="panda" mesh="link4"/>
              <inertial pos="-0.0360505 0.0337069 0.0319019" mass="2.3104763646281508"
                        fullinertia="0.007764568814864828 0.008015776929980149 0.009955882308071066 0.003371475204045935 -0.002343621113168248 0.0022917526161470624"/>

              <body name="panda_link5" pos="-0.0825 0.384 0" quat="0.7071067811865476 -0.7071067811865475 0 0">
                <joint name="panda_joint5" pos="0 0 0" axis="0 0 1" limited="true" range="-2.897246558310587 2.897246558310587" damping="3.0" frictionloss="0.48"/>
                <geom type="mesh" material="panda" mesh="link5"/>
                <inertial pos="-6.12525e-06 0.0610427 -0.104176" mass="2.6226426154892004"
                          fullinertia="0.029070538014399377 0.027638529986528795 0.004251111234400737 6.208738268725568e-07 -1.0059151925023392e-05 -0.007424306477850814"/>

                <body name="panda_link6" pos="0 0 0" quat="0.7071067811865476 0.7071067811865475 0 0">
                  <joint name="panda_joint6" pos="0 0 0" axis="0 0 1" limited="true" range="-0.017453292519943295 3.752457891787808" damping="3.0" frictionloss="0.48"/>
                  <geom type="mesh" material="panda" mesh="link6"/>
                  <inertial pos="0.051051 0.00910797 0.0106343" mass="1.5025804886626795"
                            fullinertia="0.002940555801469018 0.00392105201248677 0.0054115603870960195 -0.00042391108351381507 0.000610007735338717 0.00012647545430836214"/>

                  <body name="panda_link7" pos="0.088 0 0" quat="0.7071067811865476 0.7071067811865475 0 0">
                    <joint name="panda_joint7" pos="0 0 0" axis="0 0 1" limited="true" range="-2.897246558310587 2.897246558310587" damping="3.0" frictionloss="0.48"/>
                    <geom type="mesh" material="panda" mesh="link7"/>
                    <inertial pos="0.0109695 0.0107965 0.0650412" mass="0.5237668134788256"
                              fullinertia="0.0008621467959726535 0.0008613100184801048 0.0006961139396618219 -0.00011871071570425467 3.866602604509339e-05 -9.057841649422724e-05"/>

                    <body name="panda_link8" pos="0 0 0.107" quat="0.9238795325112867 0 0 -0.3826834323650898">
                      <body name="panda_hand">
                        <geom type="mesh" material="panda" mesh="hand"/>
                        <inertial pos="-6.7624e-06 0.00152435 0.0275912" mass="0.14060765127978503"
                                  fullinertia="0.0005365450414352072 7.70511954783727e-05 0.0004938176882694914 1.7911952957732454e-08 -2.320071910601251e-08 4.681149945315967e-08"/>

                        <body name="panda_leftfinger" pos="0 0 0.0584">
                          <joint name="panda_finger_joint1" pos="0 0 0" axis="0 1 0" type="slide" limited="true" range="0 0.04" damping="3.0" frictionloss="0.4"/>
                          <geom type="mesh" material="panda" mesh="finger"/>
                          <site name="panda_left_finger_tip" pos="0 0.005 0.045" size="0.008 0.0048 0.008" type="box" rgba="1 0 0 0.5"/>
                          <inertial pos="-6.2561e-06 0.00227781 -0.0277116" mass="0.2238453537819424"
                                    fullinertia="6.74804167363695e-05 6.627189221641395e-05 1.550396267804825e-05 -4.1027443646025676e-09 1.8693673970152995e-08 1.1967548474390802e-05"/>
                        </body>

                        <body name="panda_rightfinger" pos="0 0 0.0584" euler="0 0 3.141592653589793">
                          <joint name="panda_finger_joint2" pos="0 0 0" axis="0 1 0" type="slide" limited="true" range="0 0.04" damping="3.0" frictionloss="0.4"/>
                          <geom type="mesh" material="panda" mesh="finger" condim="1"/>
                          <site name="panda_right_finger_tip" pos="0 0.005 0.045" size="0.008 0.0048 0.008" type="box" rgba="1 0 0 0.5"/>
                          <inertial pos="-6.2561e-06 0.00227781 -0.0277116" mass="0.2238453537819424"
                                    fullinertia="6.74804167363695e-05 6.627189221641395e-05 1.550396267804825e-05 -4.1027443646025676e-09 1.8693673970152995e-08 1.1967548474390802e-05"/>
                        </body>
                      </body>
                    </body>
                  </body>
                </body>
              </body>
            </body>
          </body>
        </body>
      </body>
    </body>
  </worldbody>

  <tendon>
    <fixed name="panda_split">
      <joint joint="panda_finger_joint1" coef="0.5"/>
      <joint joint="panda_finger_joint2" coef="0.5"/>
    </fixed>
  </tendon>

  <equality>
    <joint joint1="panda_finger_joint1" joint2="panda_finger_joint2"
           solimp="0.95 0.99 0.001" solref="0.005 1"/>
  </equality>

  <sensor>
    <force site="panda_left_finger_tip" name="panda_left_finger_force"/>
    <torque site="panda_left_finger_tip" name="panda_left_finger_torque"/>
    <force site="panda_right_finger_tip" name="panda_right_finger_force"/>
    <torque site="panda_right_finger_tip" name="panda_right_finger_torque"/>
  </sensor>
</mujoco>
